(plaka_tanima_env) mm@raspberrypi:~/plk5/2 $ python app.py
Traceback (most recent call last):
  File "/home/mm/plaka_tanima_env/lib/python3.9/site-packages/sqlalchemy/engine/base.py", line 146, in __init__
    self._dbapi_connection = engine.raw_connection()
  File "/home/mm/plaka_tanima_env/lib/python3.9/site-packages/sqlalchemy/engine/base.py", line 3298, in raw_connection
    return self.pool.connect()
  File "/home/mm/plaka_tanima_env/lib/python3.9/site-packages/sqlalchemy/pool/base.py", line 449, in connect
    return _ConnectionFairy._checkout(self)
  File "/home/mm/plaka_tanima_env/lib/python3.9/site-packages/sqlalchemy/pool/base.py", line 1263, in _checkout
    fairy = _ConnectionRecord.checkout(pool)
  File "/home/mm/plaka_tanima_env/lib/python3.9/site-packages/sqlalchemy/pool/base.py", line 712, in checkout
    rec = pool._do_get()
  File "/home/mm/plaka_tanima_env/lib/python3.9/site-packages/sqlalchemy/pool/impl.py", line 180, in _do_get
    self._dec_overflow()
  File "/home/mm/plaka_tanima_env/lib/python3.9/site-packages/sqlalchemy/util/langhelpers.py", line 146, in __exit__
    raise exc_value.with_traceback(exc_tb)
  File "/home/mm/plaka_tanima_env/lib/python3.9/site-packages/sqlalchemy/pool/impl.py", line 177, in _do_get
    return self._create_connection()
  File "/home/mm/plaka_tanima_env/lib/python3.9/site-packages/sqlalchemy/pool/base.py", line 390, in _create_connection
    return _ConnectionRecord(self)
  File "/home/mm/plaka_tanima_env/lib/python3.9/site-packages/sqlalchemy/pool/base.py", line 674, in __init__
    self.__connect()
  File "/home/mm/plaka_tanima_env/lib/python3.9/site-packages/sqlalchemy/pool/base.py", line 901, in __connect
    pool.logger.debug("Error on connect(): %s", e)
  File "/home/mm/plaka_tanima_env/lib/python3.9/site-packages/sqlalchemy/util/langhelpers.py", line 146, in __exit__
    raise exc_value.with_traceback(exc_tb)
  File "/home/mm/plaka_tanima_env/lib/python3.9/site-packages/sqlalchemy/pool/base.py", line 896, in __connect
    self.dbapi_connection = connection = pool._invoke_creator(self)
  File "/home/mm/plaka_tanima_env/lib/python3.9/site-packages/sqlalchemy/engine/create.py", line 646, in connect
    return dialect.connect(*cargs, **cparams)
  File "/home/mm/plaka_tanima_env/lib/python3.9/site-packages/sqlalchemy/engine/default.py", line 622, in connect
    return self.loaded_dbapi.connect(*cargs, **cparams)
  File "/home/mm/plaka_tanima_env/lib/python3.9/site-packages/psycopg2/__init__.py", line 122, in connect
    conn = _connect(dsn, connection_factory=connection_factory, **kwasync)
psycopg2.OperationalError: connection to server at "localhost" (::1), port 5432 failed: FATAL:  password authentication failed for user "username"
connection to server at "localhost" (::1), port 5432 failed: FATAL:  password authentication failed for user "username"


The above exception was the direct cause of the following exception:

Traceback (most recent call last):
  File "/home/mm/plk5/2/app.py", line 555, in <module>
    db.create_all()
  File "/home/mm/plaka_tanima_env/lib/python3.9/site-packages/flask_sqlalchemy/extension.py", line 900, in create_all
    self._call_for_binds(bind_key, "create_all")
  File "/home/mm/plaka_tanima_env/lib/python3.9/site-packages/flask_sqlalchemy/extension.py", line 881, in _call_for_binds
    getattr(metadata, op_name)(bind=engine)
  File "/home/mm/plaka_tanima_env/lib/python3.9/site-packages/sqlalchemy/sql/schema.py", line 5907, in create_all
    bind._run_ddl_visitor(
  File "/home/mm/plaka_tanima_env/lib/python3.9/site-packages/sqlalchemy/engine/base.py", line 3248, in _run_ddl_visitor
    with self.begin() as conn:
  File "/usr/local/lib/python3.9/contextlib.py", line 119, in __enter__
    return next(self.gen)
  File "/home/mm/plaka_tanima_env/lib/python3.9/site-packages/sqlalchemy/engine/base.py", line 3238, in begin
    with self.connect() as conn:
  File "/home/mm/plaka_tanima_env/lib/python3.9/site-packages/sqlalchemy/engine/base.py", line 3274, in connect
    return self._connection_cls(self)
  File "/home/mm/plaka_tanima_env/lib/python3.9/site-packages/sqlalchemy/engine/base.py", line 148, in __init__
    Connection._handle_dbapi_exception_noconnection(
  File "/home/mm/plaka_tanima_env/lib/python3.9/site-packages/sqlalchemy/engine/base.py", line 2439, in _handle_dbapi_exception_noconnection
    raise sqlalchemy_exception.with_traceback(exc_info[2]) from e
  File "/home/mm/plaka_tanima_env/lib/python3.9/site-packages/sqlalchemy/engine/base.py", line 146, in __init__
    self._dbapi_connection = engine.raw_connection()
  File "/home/mm/plaka_tanima_env/lib/python3.9/site-packages/sqlalchemy/engine/base.py", line 3298, in raw_connection
    return self.pool.connect()
  File "/home/mm/plaka_tanima_env/lib/python3.9/site-packages/sqlalchemy/pool/base.py", line 449, in connect
    return _ConnectionFairy._checkout(self)
  File "/home/mm/plaka_tanima_env/lib/python3.9/site-packages/sqlalchemy/pool/base.py", line 1263, in _checkout
    fairy = _ConnectionRecord.checkout(pool)
  File "/home/mm/plaka_tanima_env/lib/python3.9/site-packages/sqlalchemy/pool/base.py", line 712, in checkout
    rec = pool._do_get()
  File "/home/mm/plaka_tanima_env/lib/python3.9/site-packages/sqlalchemy/pool/impl.py", line 180, in _do_get
    self._dec_overflow()
  File "/home/mm/plaka_tanima_env/lib/python3.9/site-packages/sqlalchemy/util/langhelpers.py", line 146, in __exit__
    raise exc_value.with_traceback(exc_tb)
  File "/home/mm/plaka_tanima_env/lib/python3.9/site-packages/sqlalchemy/pool/impl.py", line 177, in _do_get
    return self._create_connection()
  File "/home/mm/plaka_tanima_env/lib/python3.9/site-packages/sqlalchemy/pool/base.py", line 390, in _create_connection
    return _ConnectionRecord(self)
  File "/home/mm/plaka_tanima_env/lib/python3.9/site-packages/sqlalchemy/pool/base.py", line 674, in __init__
    self.__connect()
  File "/home/mm/plaka_tanima_env/lib/python3.9/site-packages/sqlalchemy/pool/base.py", line 901, in __connect
    pool.logger.debug("Error on connect(): %s", e)
  File "/home/mm/plaka_tanima_env/lib/python3.9/site-packages/sqlalchemy/util/langhelpers.py", line 146, in __exit__
    raise exc_value.with_traceback(exc_tb)
  File "/home/mm/plaka_tanima_env/lib/python3.9/site-packages/sqlalchemy/pool/base.py", line 896, in __connect
    self.dbapi_connection = connection = pool._invoke_creator(self)
  File "/home/mm/plaka_tanima_env/lib/python3.9/site-packages/sqlalchemy/engine/create.py", line 646, in connect
    return dialect.connect(*cargs, **cparams)
  File "/home/mm/plaka_tanima_env/lib/python3.9/site-packages/sqlalchemy/engine/default.py", line 622, in connect
    return self.loaded_dbapi.connect(*cargs, **cparams)
  File "/home/mm/plaka_tanima_env/lib/python3.9/site-packages/psycopg2/__init__.py", line 122, in connect
    conn = _connect(dsn, connection_factory=connection_factory, **kwasync)
sqlalchemy.exc.OperationalError: (psycopg2.OperationalError) connection to server at "localhost" (::1), port 5432 failed: FATAL:  password authentication failed for user "username"
connection to server at "localhost" (::1), port 5432 failed: FATAL:  password authentication failed for user "username"

(Background on this error at: https://sqlalche.me/e/20/e3q8)
